Workbook
Name Slicer_player: #N/A
Name Slicer_Player1: #N/A

Sheet Matches
A1: Match No | B1: Stage | C1: Group | D1: Date | E1: Venue | F1: City | G1: Team 1 | H1: Team 2 | I1: toss_winner | J1: Toss Winner | K1: Toss | L1: Match Winner | M1: Margin | N1: Toss winnner = match winner ?
A2: 1 | B2: Group | C2: A | D2: 46060 | E2: R. Premadasa Stadium | F2: Colombo | G2: Netherlands | H2: Pakistan | I2: Pakistan | J2: Pakistan | K2: Field | L2: Pakistan | M2: 3 wkts (3b rem) | N2: =IF(OR(L2="No Result",L2="Abandoned",L2="NA"),"NA", IF(TRIM(UPPER(J2))=TRIM(UPPER(L2)),"Yes","No")) -> Yes
A3: 2 | B3: Group | C3: C | D3: 46060 | E3: Eden Gardens | F3: Kolkata | G3: West Indies | H3: Scotland | I3: West Indies | J3: Scotland | K3: Field | L3: West Indies | M3: 35 runs | N3: =IF(OR(L3="No Result",L3="Abandoned",L3="NA"),"NA", IF(TRIM(UPPER(J3))=TRIM(UPPER(L3)),"Yes","No")) -> No
A4: 3 | B4: Group | C4: A | D4: 46060 | E4: Wankhede Stadium | F4: Mumbai | G4: India | H4: USA | I4: India | J4: USA | K4: Field | L4: India | M4: 29 runs | N4: =IF(OR(L4="No Result",L4="Abandoned",L4="NA"),"NA", IF(TRIM(UPPER(J4))=TRIM(UPPER(L4)),"Yes","No")) -> No
A5: 4 | B5: Group | C5: D | D5: 46061 | E5: M.A. Chidambaram Stadium | F5: Chennai | G5: Afghanistan | H5: New Zealand | I5: Afghanistan | J5: Afghanistan | K5: Bat | L5: New Zealand | M5: 5 wkts (13b rem) | N5: =IF(OR(L5="No Result",L5="Abandoned",L5="NA"),"NA", IF(TRIM(UPPER(J5))=TRIM(UPPER(L5)),"Yes","No")) -> No
A6: 5 | B6: Group | C6: C | D6: 46061 | E6: Wankhede Stadium | F6: Mumbai | G6: England | H6: Nepal | I6: England | J6: England | K6: Bat | L6: England | M6: 4 runs | N6: =IF(OR(L6="No Result",L6="Abandoned",L6="NA"),"NA", IF(TRIM(UPPER(J6))=TRIM(UPPER(L6)),"Yes","No")) -> Yes
A7: 6 | B7: Group | C7: B | D7: 46061 | E7: R. Premadasa Stadium | F7: Colombo | G7: Sri Lanka | H7: Ireland | I7: Sri Lanka | J7: Ireland | K7: Field | L7: Sri Lanka | M7: 20 runs | N7: =IF(OR(L7="No Result",L7="Abandoned",L7="NA"),"NA", IF(TRIM(UPPER(J7))=TRIM(UPPER(L7)),"Yes","No")) -> No
A8: 7 | B8: Group | C8: C | D8: 46062 | E8: Eden Gardens | F8: Kolkata | G8: Scotland | H8: Italy | I8: Scotland | J8: Italy | K8: Field | L8: Scotland | M8: 73 runs | N8: =IF(OR(L8="No Result",L8="Abandoned",L8="NA"),"NA", IF(TRIM(UPPER(J8))=TRIM(UPPER(L8)),"Yes","No")) -> No
A9: 8 | B9: Group | C9: B | D9: 46062 | E9: R. Premadasa Stadium | F9: Colombo | G9: Oman | H9: Zimbabwe | I9: Zimbabwe | J9: Zimbabwe | K9: Field | L9: Zimbabwe | M9: 8 Wkts (39b rem) | N9: =IF(OR(L9="No Result",L9="Abandoned",L9="NA"),"NA", IF(TRIM(UPPER(J9))=TRIM(UPPER(L9)),"Yes","No")) -> Yes
A10: 9 | B10: Group | C10: D | D10: 46062 | E10: Narendra Modi Stadium | F10: Ahmedabad | G10: South Africa | H10: Canada | I10: South Africa | J10: Canada | K10: Field | L10: South Africa | M10: 57 runs | N10: =IF(OR(L10="No Result",L10="Abandoned",L10="NA"),"NA", IF(TRIM(UPPER(J10))=TRIM(UPPER(L10)),"Yes","No")) -> No
A11: 10 | B11: Group | C11: A | D11: 46063 | E11: Arun Jaitley Stadium | F11: Delhi | G11: Namibia | H11: Netherlands | I11: Netherlands | J11: Netherlands | K11: Field | L11: Netherlands | M11: 7 wkts (12b rem) | N11: =IF(OR(L11="No Result",L11="Abandoned",L11="NA"),"NA", IF(TRIM(UPPER(J11))=TRIM(UPPER(L11)),"Yes","No")) -> Yes
A12: 11 | B12: Group | C12: D | D12: 46063 | E12: M.A. Chidambaram Stadium | F12: Chennai | G12: New Zealand | H12: UAE | I12: New Zealand | J12: UAE | K12: Bat | L12: New Zealand | M12: 10 wkts (28b rem) | N12: =IF(OR(L12="No Result",L12="Abandoned",L12="NA"),"NA", IF(TRIM(UPPER(J12))=TRIM(UPPER(L12)),"Yes","No")) -> No
A13: 12 | B13: Group | C13: A | D13: 46063 | E13: Sinhalese Sports Club | F13: Colombo | G13: Pakistan | H13: USA | I13: Pakistan | J13: USA | K13: Field | L13: Pakistan | M13: 32 runs | N13: =IF(OR(L13="No Result",L13="Abandoned",L13="NA"),"NA", IF(TRIM(UPPER(J13))=TRIM(UPPER(L13)),"Yes","No")) -> No
... A41: 40 | B41: Group | C41: B | D41: 46073 | E41: Pallekele Cricket Stadium | F41: Kandy | G41: Australia | H41: Oman | I41: Australia | J41: Australia | K41: Field | L41: Australia | M41: 9 wkts (62b rem) | N41: =IF(OR(L41="No Result",L41="Abandoned",L41="NA"),"NA", IF(TRIM(UPPER(J41))=TRIM(UPPER(L41)),"Yes","No")) -> Yes
A42: 41 | B42: Super Eight | C42: 1 | D42: 46074 | E42: R. Premadasa Stadium | F42: Colombo | G42: New Zealand | H42: Pakistan | I42: South Africa | J42: NA | K42: NA | L42: No Result | M42: Abandoned | N42: =IF(OR(L42="No Result",L42="Abandoned",L42="NA"),"NA", IF(TRIM(UPPER(J42))=TRIM(UPPER(L42)),"Yes","No")) -> NA
A43: 42 | B43: Super Eight | C43: 1 | D43: 46075 | E43: Pallekele Cricket Stadium | F43: Kandy | G43: Sri Lanka | H43: England | I43: India | J43: Sri Lanka | K43: Field | L43: England | M43: 51 runs | N43: =IF(OR(L43="No Result",L43="Abandoned",L43="NA"),"NA", IF(TRIM(UPPER(J43))=TRIM(UPPER(L43)),"Yes","No")) -> No
A44: 43 | B44: Super Eight | C44: 2 | D44: 46075 | E44: Narendra Modi Stadium | F44: Ahmedabad | G44: India | H44: South Africa | I44: England | J44: South Africa | K44: Bat | L44: South Africa | M44: 76 runs | N44: =IF(OR(L44="No Result",L44="Abandoned",L44="NA"),"NA", IF(TRIM(UPPER(J44))=TRIM(UPPER(L44)),"Yes","No")) -> Yes
A45: 44 | B45: Super Eight | C45: 2 | D45: 46076 | E45: Wankhede Stadium | F45: Mumbai | G45: Zimbabwe | H45: West Indies | I45: New Zealand | J45: Zimbabwe | K45: Field | L45: West Indies | M45: 107 runs | N45: =IF(OR(L45="No Result",L45="Abandoned",L45="NA"),"NA", IF(TRIM(UPPER(J45))=TRIM(UPPER(L45)),"Yes","No")) -> No
A46: 45 | B46: Super Eight | C46: 1 | D46: 46077 | E46: Pallekele Cricket Stadium | F46: Kandy | G46: England | H46: Pakistan | I46: England | J46: Pakistan | K46: Bat | L46: England | M46: 2 wkts (5b rem) | N46: =IF(OR(L46="No Result",L46="Abandoned",L46="NA"),"NA", IF(TRIM(UPPER(J46))=TRIM(UPPER(L46)),"Yes","No")) -> No
A47: 46 | B47: Super Eight | C47: 1 | D47: 46078 | E47: R. Premadasa Stadium | F47: Colombo | G47: Sri Lanka | H47: New Zealand | I47: India | J47: Sri Lanka | K47: Field | L47: New Zealand | M47: 61 runs | N47: =IF(OR(L47="No Result",L47="Abandoned",L47="NA"),"NA", IF(TRIM(UPPER(J47))=TRIM(UPPER(L47)),"Yes","No")) -> No
A48: 47 | B48: Super Eight | C48: 2 | D48: 46079 | E48: Narendra Modi Stadium | F48: Ahmedabad | G48: West Indies | H48: South Africa | I48: South Africa | J48: South Africa | K48: Field | L48: South Africa | M48: 9 wkts (23b rem) | N48: =IF(OR(L48="No Result",L48="Abandoned",L48="NA"),"NA", IF(TRIM(UPPER(J48))=TRIM(UPPER(L48)),"Yes","No")) -> Yes
A49: 48 | B49: Super Eight | C49: 2 | D49: 46079 | E49: M.A. Chidambaram Stadium | F49: Chennai | G49: India | H49: Zimbabwe | I49: England | J49: Zimbabwe | K49: Field | L49: India | M49: 72 runs | N49: =IF(OR(L49="No Result",L49="Abandoned",L49="NA"),"NA", IF(TRIM(UPPER(J49))=TRIM(UPPER(L49)),"Yes","No")) -> No
A50: 49 | B50: Super Eight | C50: 1 | D50: 46080 | E50: R. Premadasa Stadium | F50: Colombo | G50: England | H50: New Zealand | I50: South Africa | J50: New Zealand | K50: Bat | L50: England | M50: 4 wkts | N50: =IF(OR(L50="No Result",L50="Abandoned",L50="NA"),"NA", IF(TRIM(UPPER(J50))=TRIM(UPPER(L50)),"Yes","No")) -> No
A51: 50 | B51: Super Eight | C51: 2 | D51: 46081 | E51: Pallekele Cricket Stadium | F51: Kandy | G51: Sri Lanka | H51: Pakistan | I51: New Zealand | J51: Sri Lanka | K51: Field | L51: Pakistan | M51: 5 runs | N51: =IF(OR(L51="No Result",L51="Abandoned",L51="NA"),"NA", IF(TRIM(UPPER(J51))=TRIM(UPPER(L51)),"Yes","No")) -> No
A52: 51 | B52: Super Eight | C52: 1 | D52: 46082 | E52: Arun Jaitley Stadium | F52: Delhi | G52: Zimbabwe | H52: South Africa | I52: South Africa | J52: Zimbabwe | K52: Bat | L52: South Africa | M52: 5 wkts | N52: =IF(OR(L52="No Result",L52="Abandoned",L52="NA"),"NA", IF(TRIM(UPPER(J52))=TRIM(UPPER(L52)),"Yes","No")) -> No
A53: 52 | B53: Super Eight | C53: 1 | D53: 46082 | E53: Eden Gardens | F53: Kolkata | G53: India | H53: West Indies | I53: India | J53: India | K53: Field | L53: India | M53: 5 wkts (4b rem) | N53: =IF(OR(L53="No Result",L53="Abandoned",L53="NA"),"NA", IF(TRIM(UPPER(J53))=TRIM(UPPER(L53)),"Yes","No")) -> Yes
A54: 53 | B54: Semi-Final | C54: SF1 | D54: 46085 | E54: Eden Gardens | F54: Kolkata | G54: South Africa | H54: New Zealand | J54: New Zealand | K54: Field | L54: New Zealand | M54: 9 wkts (43b rem) | N54: =IF(OR(L54="No Result",L54="Abandoned",L54="NA"),"NA", IF(TRIM(UPPER(J54))=TRIM(UPPER(L54)),"Yes","No")) -> Yes
A55: 54 | B55: Semi-Final | C55: SF2 | D55: 46086 | E55: Wankhede Stadium | F55: Mumbai | G55: India | H55: England | I55: India | J55: England | K55: Field | L55: India | M55: 7 runs | N55: =IF(OR(L55="No Result",L55="Abandoned",L55="NA"),"NA", IF(TRIM(UPPER(J55))=TRIM(UPPER(L55)),"Yes","No")) -> No
A56: 55 | B56: Final | C56: Final | D56: 46089 | E56: Narendra Modi Stadium | F56: Ahmedabad | G56: India | H56: New Zealand | I56: India | J56: New Zealand | K56: Field | L56: India | M56: 96 runs | N56: =IF(OR(L56="No Result",L56="Abandoned",L56="NA"),"NA", IF(TRIM(UPPER(J56))=TRIM(UPPER(L56)),"Yes","No")) -> No
E68: Win Types | F68: Matches
E69: Chasing Wins | F69: =COUNTIF(M1:M55,"*wkts*") -> 23
E70: Defending Wins | F70: =COUNTIF(M3:M57,"*run*") -> 29
E71: No Result | F71: =COUNTIF(M1:M55,"*Abandoned*") -> 2
E72: Super Over | F72: =COUNTIF(M3:M57,"*Super Over*") -> 1

Sheet Venues
A1: Venue Name | B1: City | C1: Country | D1: Capacity | E1: Stages Hosted | F1: Average Score 1st Inning | G1: Average Score 2nd Inning
A2: Narendra Modi Stadium | B2: Ahmedabad | C2: India | D2: 132000 | E2: Group D, Super Eight Group 1, Semi-Final 1, Final | F2: 189 | G2: 161
A3: Wankhede Stadium | B3: Mumbai | C3: India | D3: 33000 | E3: Group C, Super Eight Group 1, Semi-Final 2 | F3: 175 | G3: 158
A4: Eden Gardens | B4: Kolkata | C4: India | D4: 68000 | E4: Group C, Super Eight Group 1 | F4: 172 | G4: 145
A5: M.A. Chidambaram Stadium | B5: Chennai | C5: India | D5: 50000 | E5: Group D, Super Eight Group 2 | F5: 165 | G5: 145
A6: Arun Jaitley Stadium | B6: Delhi | C6: India | D6: 41000 | E6: Group A/D, Super Eight Group 1 | F6: 172 | G6: 155
A7: R. Premadasa Stadium | B7: Colombo | C7: Sri Lanka | D7: 35000 | E7: Group A/B, Super Eight Group 1/2 | F7: 165 | G7: 145
A8: Sinhalese Sports Club | B8: Colombo | C8: Sri Lanka | D8: 10000 | E8: Group A | F8: 175 | G8: 155
A9: Pallekele Cricket Stadium | B9: Kandy | C9: Sri Lanka | D9: 35000 | E9: Group B, Super Eight Group 1/2 | F9: 165 | G9: 144

Sheet Points Table
A1: GROUP | B1: TEAM | C1: MATCHES PLAYED | D1: WON | E1: LOST | F1: NO RESULT | G1: NRR | H1: POINTS | I1: QUALIFIED
A2: A | B2: India | C2: 5 | D2: 5 | E2: 0 | F2: 0 | G2: 3.12 | H2: 10 | I2: Yes
A3: A | B3: Pakistan | C3: 5 | D3: 4 | E3: 1 | F3: 0 | G3: 1.85 | H3: 8 | I3: Yes
A4: A | B4: Netherlands | C4: 5 | D4: 2 | E4: 3 | F4: 0 | G4: -0.45 | H4: 4 | I4: No
A5: A | B5: USA | C5: 5 | D5: 1 | E5: 4 | F5: 0 | G5: -1.2 | H5: 2 | I5: No
A6: A | B6: Namibia | C6: 5 | D6: 0 | E6: 5 | F6: 0 | G6: -3.1 | H6: 0 | I6: No
A8: B | B8: Sri Lanka | C8: 5 | D8: 4 | E8: 1 | F8: 0 | G8: 1.95 | H8: 8 | I8: Yes
A9: B | B9: Zimbabwe | C9: 5 | D9: 3 | E9: 1 | F9: 1 | G9: 0.65 | H9: 7 | I9: Yes
A10: B | B10: Australia | C10: 5 | D10: 2 | E10: 2 | F10: 1 | G10: 0.3 | H10: 5 | I10: No
A11: B | B11: Ireland | C11: 5 | D11: 1 | E11: 3 | F11: 1 | G11: -0.85 | H11: 3 | I11: No
A12: B | B12: Oman | C12: 5 | D12: 0 | E12: 5 | F12: 0 | G12: -2.05 | H12: 0 | I12: No
A14: C | B14: England | C14: 5 | D14: 5 | E14: 0 | F14: 0 | G14: 2.5 | H14: 10 | I14: Yes
A15: C | B15: West Indies | C15: 5 | D15: 3 | E15: 2 | F15: 0 | G15: 0.8 | H15: 6 | I15: Yes
... A34: SE2 | B34: Sri Lanka | C34: 3 | D34: 0 | E34: 3 | F34: 0 | G34: -1.5 | H34: 0 | I34: No

Sheet Batting Stats
A1: Player | B1: Team | C1: Matches | D1: Innings | E1: Runs | F1: Average | G1: Strike_Rate | H1: Fours | I1: Sixes | J1: Hundreds | K1: Fifties
A2: Sahibzada Farhan | B2: Pakistan | C2: 7 | D2: 6 | E2: 383 | F2: 76.6 | G2: 160.25 | H2: 37 | I2: 18 | J2: 2 | K2: 1
A3: Tim Seifert | B3: New Zealand | C3: 9 | D3: 8 | E3: 326 | F3: 46.57 | G3: 166.33 | H3: 34 | I3: 16 | J3: 0 | K3: 4
A4: Sanju Samson | B4: India | C4: 5 | D4: 5 | E4: 321 | F4: 80.25 | G4: 199.38 | H4: 27 | I4: 24 | J4: 0 | K4: 4
A5: Ishan Kishan | B5: India | C5: 9 | D5: 9 | E5: 317 | F5: 35.22 | G5: 193.29 | H5: 33 | I5: 18 | J5: 0 | K5: 3
A6: Finn Allen | B6: New Zealand | C6: 8 | D6: 8 | E6: 298 | F6: 49.67 | G6: 200 | H6: 25 | I6: 20 | J6: 1 | K6: 1
A7: Brian Bennett | B7: Zimbabwe | C7: 6 | D7: 6 | E7: 292 | F7: 146 | G7: 134.56 | H7: 32 | I7: 7 | J7: 0 | K7: 3
A8: Aiden Markram | B8: South Africa | C8: 8 | D8: 8 | E8: 286 | F8: 47.67 | G8: 165.32 | H8: 32 | I8: 11 | J8: 0 | K8: 2
A9: Jacob Bethell | B9: England | C9: 8 | D9: 8 | E9: 280 | F9: 35 | G9: 152.17 | H9: 25 | I9: 14 | J9: 1 | K9: 1
A10: Shimron Hetmyer | B10: West Indies | C10: 7 | D10: 7 | E10: 248 | F10: 41.33 | G10: 186.47 | H10: 16 | I10: 19 | J10: 0 | K10: 2
A11: Suryakumar Yadav | B11: India | C11: 9 | D11: 9 | E11: 242 | F11: 30.25 | G11: 136.72 | H11: 21 | I11: 10 | J11: 0 | K11: 2
A12: Will Jacks | B12: England | C12: 8 | D12: 8 | E12: 226 | F12: 32.29 | G12: 155.17 | H12: 18 | I12: 9 | J12: 0 | K12: 1
A13: Pathum Nissanka | B13: Sri Lanka | C13: 7 | D13: 7 | E13: 208 | F13: 29.71 | G13: 138.67 | H13: 20 | I13: 8 | J13: 1 | K13: 1
... A20: Daryl Mitchell | B20: New Zealand | C20: 9 | D20: 9 | E20: 168 | F20: 21 | G20: 130.23 | H20: 16 | I20: 5 | J20: 0 | K20: 1

Sheet Bowling Stats
A1: Player | B1: Team | C1: Matches | D1: Overs | E1: Balls | F1: Wickets | G1: Average | H1: Runs_Conceeded | I1: Economy | J1: 4W_Hauls | K1: 5W_Hauls | L1: Best_Figures
A2: Jasprit Bumrah | B2: India | C2: 8 | D2: 28 | E2: 168 | F2: 14 | G2: 12.43 | H2: 174 | I2: 6.21 | J2: 1 | K2: 0 | L2: 4/15
A3: Varun Chakravarthy | B3: India | C3: 9 | D3: 31 | E3: 186 | F3: 14 | G3: 20.5 | H3: 287 | I3: 9.26 | J3: 0 | K3: 0 | L3: 3/27
A4: Shadley van Schalkwyk | B4: USA | C4: 4 | D4: 14.5 | E4: 89 | F4: 13 | G4: 7.77 | H4: 101 | I4: 6.81 | J4: 2 | K4: 0 | L4: 4/18
A5: Blessing Muzarabani | B5: Zimbabwe | C5: 6 | D5: 23.5 | E5: 143 | F5: 13 | G5: 14.46 | H5: 188 | I5: 7.93 | J5: 1 | K5: 0 | L5: 4/28
A6: Adil Rashid | B6: England | C6: 8 | D6: 30.4 | E6: 184 | F6: 13 | G6: 19.23 | H6: 250 | I6: 8.15 | J6: 0 | K6: 0 | L6: 3/22
A7: Lungi Ngidi | B7: South Africa | C7: 7 | D7: 26 | E7: 156 | F7: 12 | G7: 15.58 | H7: 187 | I7: 7.19 | J7: 1 | K7: 0 | L7: 4/25
A8: Rachin Ravindra | B8: New Zealand | C8: 9 | D8: 19 | E8: 114 | F8: 12 | G8: 12.42 | H8: 149 | I8: 7.84 | J8: 1 | K8: 0 | L8: 4/19
A9: Marco Jansen | B9: South Africa | C9: 6 | D9: 22.4 | E9: 136 | F9: 11 | G9: 21.55 | H9: 237 | I9: 10.47 | J9: 2 | K9: 0 | L9: 4/30
A10: Maheesh Theekshana | B10: Sri Lanka | C10: 7 | D10: 27.3 | E10: 165 | F10: 11 | G10: 18.55 | H10: 204 | I10: 7.42 | J10: 0 | K10: 0 | L10: 3/18
A11: Corbin Bosch | B11: South Africa | C11: 7 | D11: 25 | E11: 150 | F11: 11 | G11: 17.36 | H11: 191 | I11: 7.64 | J11: 0 | K11: 0 | L11: 3/20
A12: Axar Patel | B12: India | C12: 9 | D12: 30 | E12: 180 | F12: 10 | G12: 19.8 | H12: 198 | I12: 6.6 | J12: 0 | K12: 0 | L12: 3/27
A13: Romario Shepherd | B13: West Indies | C13: 7 | D13: 24 | E13: 144 | F13: 10 | G13: 9 | H13: 90 | I13: 3.75 | J13: 0 | K13: 1 | L13: 5/20
... A16: Lockie Ferguson | B16: New Zealand | C16: 9 | D16: 33 | E16: 198 | F16: 9 | G16: 24.67 | H16: 222 | I16: 6.73 | J16: 0 | K16: 0 | L16: 3/30

Sheet Records
A1: Award | B1: Player Name | C1: Team
A2: Player of the Tournament | B2: Sanju Samson | C2: India
A3: Most Runs | B3: Sahibzada Farhan | C3: Pakistan
A4: Most Wickets (Joint) | B4: Jasprit Bumrah | C4: India
A5: Most Wickets (Joint) | B5: Varun Chakravarthy | C5: India
A6: Fastest Century | B6: Finn Allen | C6: New Zealand
A7: Best Bowling Figures | B7: Romario Shepherd | C7: West Indies
A8: Highest Individual Score in Final | B8: Sanju Samson (89) | C8: India
A9: Highest Team Total in Final | B9: India 255/5 | C9: India

Sheet Dashboard

Sheet Pivot
A3: Row Labels | B3: Count of Match Winner | G3: Row Labels | H3: Sum of runs | K3: Row Labels | L3: Sum of Wickets | M3: Sum of Economy
A4: India | B4: 8 | G4: Sahibzada Farhan | H4: 383 | K4: Varun Chakravarthy | L4: 14 | M4: 9.26
A5: South Africa | B5: 7 | G5: Tim Seifert | H5: 326 | K5: Jasprit Bumrah | L5: 14 | M5: 6.21
A6: England | B6: 6 | G6: Sanju Samson | H6: 321 | K6: Blessing Muzarabani | L6: 13 | M6: 7.93
A7: West Indies | B7: 5 | G7: Ishan Kishan | H7: 317 | K7: Shadley van Schalkwyk | L7: 13 | M7: 6.81
A8: New Zealand | B8: 5 | G8: Finn Allen | H8: 298 | K8: Adil Rashid | L8: 13 | M8: 8.15
A9: Pakistan | B9: 4 | G9: Brian Bennett | H9: 292 | K9: Rachin Ravindra | L9: 12 | M9: 7.84
A10: Sri Lanka | B10: 3 | G10: Aiden Markram | H10: 286 | K10: Lungi Ngidi | L10: 12 | M10: 7.19
A11: Zimbabwe | B11: 3 | G11: Jacob Bethell | H11: 280 | K11: Corbin Bosch | L11: 11 | M11: 7.64
A12: Australia | B12: 2 | G12: Shimron Hetmyer | H12: 248 | K12: Marco Jansen | L12: 11 | M12: 10.47
A13: USA | B13: 2 | G13: Suryakumar Yadav | H13: 242 | K13: Maheesh Theekshana | L13: 11 | M13: 7.42
A14: No Result | B14: 2 | G14: Will Jacks | H14: 226 | K14: Axar Patel | L14: 10 | M14: 6.6
A15: Afghanistan | B15: 2 | G15: Pathum Nissanka | H15: 208 | K15: Romario Shepherd | L15: 10 | M15: 3.75
... A19: Nepal | B19: 1 | G19: Dasun Shanaka | H19: 175 | K19: Grand Total | L19: 172 | M19: 110.45
A20: Italy | B20: 1 | G20: Dewald Brevis | H20: 172
A21: Scotland | B21: 1 | G21: Daryl Mitchell | H21: 168
A22: Grand Total | B22: 55 | G22: Rachin Ravindra | H22: 149 | K22: Most Wkts + Less Eco. | L22: =INDEX(K4:K18, MATCH(_xlfn.MINIFS(M4:M18, L4:L18, MAX(L4:L18)), M4:M18, 0)) -> Jasprit Bumrah
G23: Grand Total | H23: 4689
A24: Most Wins | B24: =INDEX(A4:A21, MATCH(MAX(B4:B21), B4:B21, 0)) -> India | G24: Most Runs | H24: =INDEX(G4:G22, MATCH(MAX(H4:H22), H4:H22, 0)) -> Sahibzada Farhan
A27: Row Labels | B27: Sum of runs | C27: Sum of fours | D27: Sum of sixes | E27: Sum of strike_rate | H27: Row Labels | I27: Sum of Wickets | J27: Sum of Economy | K27: Sum of 4W_Hauls | L27: Sum of Average
A28: Will Jacks | B28: 226 | C28: 18 | D28: 9 | E28: 155.17 | H28: Hardik Pandya | I28: 9 | J28: 7.54 | K28: 0 | L28: 23.44
A29: Grand Total | B29: 226 | C29: 18 | D29: 9 | E29: 155.17 | H29: Grand Total | I29: 9 | J29: 7.54 | K29: 0 | L29: 23.44
A40: Row Labels | B40: Sum of Matches
A41: Chasing Wins | B41: 23
A42: Defending Wins | B42: 29
A43: No Result | B43: 2
A44: Super Over | B44: 1
A45: Grand Total | B45: 55
H51: =GETPIVOTDATA("Sum of Wickets",$H$27,"Player","Adil Rashid") -> #REF!
B53: =Pivot!A28 -> Will Jacks | C53: =Pivot!B28 -> 226 | D53: =Pivot!C28 -> 18 | E53: =Pivot!D28 -> 9 | F53: =Pivot!E28 -> 155.17 | H53: =Pivot!H28 -> Hardik Pandya | I53: =Pivot!I28 -> 9 | J53: =Pivot!J28 -> 7.54 | K53: =Pivot!K28 -> 0 | L53: =Pivot!L28 -> 23.44
B54: =Pivot!A29 -> Grand Total | C54: =Pivot!B29 -> 226 | D54: =Pivot!C29 -> 18 | E54: =Pivot!D29 -> 9 | F54: =Pivot!E29 -> 155.17 | H54: =Pivot!H29 -> Grand Total | I54: =Pivot!I29 -> 9 | J54: =Pivot!J29 -> 7.54 | K54: =Pivot!K29 -> 0 | L54: =Pivot!L29 -> 23.44
B55: =Pivot!A30 -> 0 | C55: =Pivot!B30 -> 0 | D55: =Pivot!C30 -> 0 | E55: =Pivot!D30 -> 0 | F55: =Pivot!E30 -> 0 | H55: =Pivot!H30 -> 0 | I55: =Pivot!I30 -> 0 | J55: =Pivot!J30 -> 0 | K55: =Pivot!K30 -> 0 | L55: =Pivot!L30 -> 0
B56: =Pivot!A31 -> 0 | C56: =Pivot!B31 -> 0 | D56: =Pivot!C31 -> 0 | E56: =Pivot!D31 -> 0 | F56: =Pivot!E31 -> 0 | H56: =Pivot!H31 -> 0 | I56: =Pivot!I31 -> 0 | J56: =Pivot!J31 -> 0 | K56: =Pivot!K31 -> 0 | L56: =Pivot!L31 -> 0
B57: =Pivot!A32 -> 0 | C57: =Pivot!B32 -> 0 | D57: =Pivot!C32 -> 0 | E57: =Pivot!D32 -> 0 | F57: =Pivot!E32 -> 0 | H57: =Pivot!H32 -> 0 | I57: =Pivot!I32 -> 0 | J57: =Pivot!J32 -> 0 | K57: =Pivot!K32 -> 0 | L57: =Pivot!L32 -> 0
B58: =Pivot!A33 -> 0 | C58: =Pivot!B33 -> 0 | D58: =Pivot!C33 -> 0 | E58: =Pivot!D33 -> 0 | F58: =Pivot!E33 -> 0 | H58: =Pivot!H33 -> 0 | I58: =Pivot!I33 -> 0 | J58: =Pivot!J33 -> 0 | K58: =Pivot!K33 -> 0 | L58: =Pivot!L33 -> 0
B59: =Pivot!A34 -> 0 | C59: =Pivot!B34 -> 0 | D59: =Pivot!C34 -> 0 | E59: =Pivot!D34 -> 0 | F59: =Pivot!E34 -> 0 | H59: =Pivot!H34 -> 0 | I59: =Pivot!I34 -> 0 | J59: =Pivot!J34 -> 0 | K59: =Pivot!K34 -> 0 | L59: =Pivot!L34 -> 0
B60: =Pivot!A35 -> 0 | C60: =Pivot!B35 -> 0 | D60: =Pivot!C35 -> 0 | E60: =Pivot!D35 -> 0 | F60: =Pivot!E35 -> 0 | H60: =Pivot!H35 -> 0 | I60: =Pivot!I35 -> 0 | J60: =Pivot!J35 -> 0 | K60: =Pivot!K35 -> 0 | L60: =Pivot!L35 -> 0
B61: =Pivot!A36 -> 0 | C61: =Pivot!B36 -> 0 | D61: =Pivot!C36 -> 0 | E61: =Pivot!D36 -> 0 | F61: =Pivot!E36 -> 0 | H61: =Pivot!H36 -> 0 | I61: =Pivot!I36 -> 0 | J61: =Pivot!J36 -> 0 | K61: =Pivot!K36 -> 0 | L61: =Pivot!L36 -> 0
B62: =Pivot!A37 -> 0 | C62: =Pivot!B37 -> 0 | D62: =Pivot!C37 -> 0 | E62: =Pivot!D37 -> 0 | F62: =Pivot!E37 -> 0 | H62: =Pivot!H37 -> 0 | I62: =Pivot!I37 -> 0 | J62: =Pivot!J37 -> 0 | K62: =Pivot!K37 -> 0 | L62: =Pivot!L37 -> 0
B63: =Pivot!A38 -> 0 | C63: =Pivot!B38 -> 0 | D63: =Pivot!C38 -> 0 | E63: =Pivot!D38 -> 0 | F63: =Pivot!E38 -> 0 | H63: =Pivot!H38 -> 0 | I63: =Pivot!I38 -> 0 | J63: =Pivot!J38 -> 0 | K63: =Pivot!K38 -> 0 | L63: =Pivot!L38 -> 0
...
